<?xml version="1.0" ?>
<!-- =================================================================================== -->
<!-- |    This document was autogenerated by xacro from /home/the0/arcturus/AllSeaingVehicle2/install/share/wamv_gazebo/urdf/wamv_gazebo.urdf.xacro | -->
<!-- |    EDITING THIS FILE BY HAND IS NOT RECOMMENDED                                 | -->
<!-- =================================================================================== -->
<!-- Basic WAM-V with gazebo plugins for dynamics -->
<robot name="WAM-V">
  <link name="wamv/left_battery_link">
    <visual>
      <origin rpy="0 0 0" xyz="0 -1.03 -.45"/>
      <geometry>
        <mesh filename="package://vrx_gazebo/models/battery/mesh/battery.dae"/>
      </geometry>
    </visual>
    <collision name="left_battery_collision">
      <origin rpy="0 0 0" xyz="0 0 .15"/>
      <geometry>
        <box size=".6 .4 .31"/>
      </geometry>
    </collision>
    <inertial>
      <origin rpy=" 0 0 0" xyz="0 0 .15"/>
      <mass value="23.5"/>
      <inertia ixx="0.5015291666666667" ixy="0" ixz="0" iyy="0.8931958333333333" iyz="0" izz="1.0183333333333333"/>
    </inertial>
  </link>
  <joint name="wamv/left_chasis_battery_joint" type="fixed">
    <origin rpy="0 0 0" xyz="0 1 0.45"/>
    <parent link="wamv/base_link"/>
    <child link="wamv/left_battery_link"/>
  </joint>
  <gazebo reference="wamv/left_battery_link">
    <visual>
      <material>
        <diffuse>1.0 1.0 1.0</diffuse>
        <specular>1.0 1.0 1.0</specular>
        <pbr>
          <metal>
            <albedo_map>model://vrx_gazebo/models/battery/mesh/battery_Albedo.png</albedo_map>
            <normal_map>model://vrx_gazebo/models/battery/mesh/battery_Normal.png</normal_map>
            <roughness_map>model://vrx_gazebo/models/battery/mesh/battery_Roughness.png</roughness_map>
            <metalness_map>model://vrx_gazebo/models/battery/mesh/battery_Metalness.png</metalness_map>
          </metal>
        </pbr>
      </material>
    </visual>
  </gazebo>
  <link name="wamv/right_battery_link">
    <visual>
      <origin rpy="0 0 0" xyz="0 -1.03 -.45"/>
      <geometry>
        <mesh filename="package://vrx_gazebo/models/battery/mesh/battery.dae"/>
      </geometry>
    </visual>
    <collision name="right_battery_collision">
      <origin rpy="0 0 0" xyz="0 0 .15"/>
      <geometry>
        <box size=".6 .4 .31"/>
      </geometry>
    </collision>
    <inertial>
      <origin rpy=" 0 0 0" xyz="0 0 .15"/>
      <mass value="23.5"/>
      <inertia ixx="0.5015291666666667" ixy="0" ixz="0" iyy="0.8931958333333333" iyz="0" izz="1.0183333333333333"/>
    </inertial>
  </link>
  <joint name="wamv/right_chasis_battery_joint" type="fixed">
    <origin rpy="0 0 0" xyz="0 -1 0.45"/>
    <parent link="wamv/base_link"/>
    <child link="wamv/right_battery_link"/>
  </joint>
  <gazebo reference="wamv/right_battery_link">
    <visual>
      <material>
        <diffuse>1.0 1.0 1.0</diffuse>
        <specular>1.0 1.0 1.0</specular>
        <pbr>
          <metal>
            <albedo_map>model://vrx_gazebo/models/battery/mesh/battery_Albedo.png</albedo_map>
            <normal_map>model://vrx_gazebo/models/battery/mesh/battery_Normal.png</normal_map>
            <roughness_map>model://vrx_gazebo/models/battery/mesh/battery_Roughness.png</roughness_map>
            <metalness_map>model://vrx_gazebo/models/battery/mesh/battery_Metalness.png</metalness_map>
          </metal>
        </pbr>
      </material>
    </visual>
  </gazebo>
  <!-- Basic model of the 16' WAM-V USV -->
  <link name="wamv/base_link">
    <visual>
      <geometry>
        <mesh filename="package://wamv_description/models/WAM-V-Base/mesh/WAM-V-Base.dae"/>
      </geometry>
    </visual>
    <!-- Main float -->
    <collision name="left_float">
      <origin rpy="0 1.57 0" xyz="-0.4 1.03 0.2"/>
      <geometry>
        <cylinder length="4" radius="0.2"/>
      </geometry>
    </collision>
    <collision name="left_mid_float">
      <origin rpy="0 1.38 0" xyz="1.85 1.03 0.3"/>
      <geometry>
        <cylinder length="0.5" radius="0.17"/>
      </geometry>
    </collision>
    <collision name="left_front_float">
      <origin rpy="0 1.3 0" xyz="2.3 1.03 0.4"/>
      <geometry>
        <cylinder length="0.45" radius="0.12"/>
      </geometry>
    </collision>
    <!-- Front beam -->
    <collision name="front_left_beam_lower">
      <origin rpy="0.78 0 0" xyz="0.9 0.85 1"/>
      <geometry>
        <cylinder length="0.5" radius="0.04"/>
      </geometry>
    </collision>
    <collision name="front_left_beam_upper">
      <origin rpy="1.35 0 0" xyz="0.9 0.6 1.18"/>
      <geometry>
        <cylinder length="0.2" radius="0.04"/>
      </geometry>
    </collision>
    <!-- Mid beam -->
    <collision name="mid_left_beam_lower">
      <origin rpy="0.1 0.25 0" xyz="-0.65 0.99 0.7"/>
      <geometry>
        <cylinder length="0.45" radius="0.03"/>
      </geometry>
    </collision>
    <collision name="mid_left_beam_medium">
      <origin rpy="0.75 0.25 0" xyz="-0.57 0.87 1.05"/>
      <geometry>
        <cylinder length="0.32" radius="0.03"/>
      </geometry>
    </collision>
    <collision name="mid_left_beam_upper">
      <origin rpy="1.35 0.25 0" xyz="-0.55 0.65 1.17"/>
      <geometry>
        <cylinder length="0.3" radius="0.03"/>
      </geometry>
    </collision>
    <!-- Rear beam -->
    <collision name="rear_left_beam_lower">
      <origin rpy="0 -0.15 0" xyz="-0.74 1.03 0.7"/>
      <geometry>
        <cylinder length="0.45" radius="0.03"/>
      </geometry>
    </collision>
    <collision name="rear_left_beam_medium">
      <origin rpy="0.75 -0.15 0" xyz="-0.79 0.91 1.05"/>
      <geometry>
        <cylinder length="0.32" radius="0.03"/>
      </geometry>
    </collision>
    <collision name="rear_left_beam_upper">
      <origin rpy="1.45 -0.15 0" xyz="-0.81 0.67 1.18"/>
      <geometry>
        <cylinder length="0.3" radius="0.03"/>
      </geometry>
    </collision>
    <!-- Joint -->
    <collision name="left_joint">
      <origin rpy="0 -0.6 0" xyz="0.58 1.03 0.6"/>
      <geometry>
        <box size="0.65 0.2 0.1"/>
      </geometry>
    </collision>
    <!-- Main float -->
    <collision name="right_float">
      <origin rpy="0 1.57 0" xyz="-0.4 -1.03 0.2"/>
      <geometry>
        <cylinder length="4" radius="0.2"/>
      </geometry>
    </collision>
    <collision name="right_mid_float">
      <origin rpy="0 1.38 0" xyz="1.85 -1.03 0.3"/>
      <geometry>
        <cylinder length="0.5" radius="0.17"/>
      </geometry>
    </collision>
    <collision name="right_front_float">
      <origin rpy="0 1.3 0" xyz="2.3 -1.03 0.4"/>
      <geometry>
        <cylinder length="0.45" radius="0.12"/>
      </geometry>
    </collision>
    <!-- Front beam -->
    <collision name="front_right_beam_lower">
      <origin rpy="-0.78 0 0" xyz="0.9 -0.85 1"/>
      <geometry>
        <cylinder length="0.5" radius="0.04"/>
      </geometry>
    </collision>
    <collision name="front_right_beam_upper">
      <origin rpy="-1.35 0 0" xyz="0.9 -0.6 1.18"/>
      <geometry>
        <cylinder length="0.2" radius="0.04"/>
      </geometry>
    </collision>
    <!-- Mid beam -->
    <collision name="mid_right_beam_lower">
      <origin rpy="-0.1 0.25 0" xyz="-0.65 -0.99 0.7"/>
      <geometry>
        <cylinder length="0.45" radius="0.03"/>
      </geometry>
    </collision>
    <collision name="mid_right_beam_medium">
      <origin rpy="-0.75 0.25 0" xyz="-0.57 -0.87 1.05"/>
      <geometry>
        <cylinder length="0.32" radius="0.03"/>
      </geometry>
    </collision>
    <collision name="mid_right_beam_upper">
      <origin rpy="-1.35 0.25 0" xyz="-0.55 -0.65 1.17"/>
      <geometry>
        <cylinder length="0.3" radius="0.03"/>
      </geometry>
    </collision>
    <!-- Rear beam -->
    <collision name="rear_right_beam_lower">
      <origin rpy="0 -0.15 0" xyz="-0.74 -1.03 0.7"/>
      <geometry>
        <cylinder length="0.45" radius="0.03"/>
      </geometry>
    </collision>
    <collision name="rear_right_beam_medium">
      <origin rpy="-0.75 -0.15 0" xyz="-0.79 -0.91 1.05"/>
      <geometry>
        <cylinder length="0.32" radius="0.03"/>
      </geometry>
    </collision>
    <collision name="rear_right_beam_upper">
      <origin rpy="-1.45 -0.15 0" xyz="-0.81 -0.67 1.18"/>
      <geometry>
        <cylinder length="0.3" radius="0.03"/>
      </geometry>
    </collision>
    <!-- Joint -->
    <collision name="right_joint">
      <origin rpy="0 -0.6 0" xyz="0.58 -1.03 0.6"/>
      <geometry>
        <box size="0.65 0.2 0.1"/>
      </geometry>
    </collision>
    <!-- Top base -->
    <collision name="top_base">
      <origin rpy="0 0 0" xyz="0 -0 1.25"/>
      <geometry>
        <box size="1.85 1 0.1"/>
      </geometry>
    </collision>
    <inertial>
      <!-- From WAM-V spec sheet -->
      <mass value="180.0"/>
      <inertia ixx="120.0" ixy="0.0" ixz="0.0" iyy="393" iyz="0.0" izz="446.0"/>
    </inertial>
  </link>
  <gazebo>
    <enable_wind>true</enable_wind>
  </gazebo>
  <gazebo reference="wamv/base_link">
    <visual>
      <material>
        <diffuse>1.0 1.0 1.0</diffuse>
        <specular>1.0 1.0 1.0</specular>
        <pbr>
          <metal>
            <albedo_map>model://wamv_description/models/WAM-V-Base/mesh/WAM-V_Albedo.png</albedo_map>
            <normal_map>model://wamv_description/models/WAM-V-Base/mesh/WAM-V_Normal.png</normal_map>
            <roughness_map>model://wamv_description/models/WAM-V-Base/mesh/WAM-V_Roughness.png</roughness_map>
            <metalness_map>model://wamv_description/models/WAM-V-Base/mesh/WAM-V_Metalness.png</metalness_map>
          </metal>
        </pbr>
      </material>
    </visual>
    <sensor name="contact_sensor" type="contact">
      <contact>
        <!-- collisions are renamed during urdf -> sdf fixed joint lumping -->
        <collision>wamv/base_link_fixed_joint_lump__top_base_collision_24</collision>
        <collision>wamv/base_link_fixed_joint_lump__left_float_collision</collision>
        <collision>wamv/base_link_fixed_joint_lump__left_mid_float_collision_1</collision>
        <collision>wamv/base_link_fixed_joint_lump__left_front_float_collision_2</collision>
        <collision>wamv/base_link_fixed_joint_lump__right_float_collision_12</collision>
        <collision>wamv/base_link_fixed_joint_lump__right_mid_float_collision_13</collision>
        <collision>wamv/base_link_fixed_joint_lump__right_front_float_collision_14</collision>
        <topic>/vrx/contacts</topic>
      </contact>
      <always_on>1</always_on>
      <update_rate>5</update_rate>
    </sensor>
  </gazebo>
  <link name="wamv/front_left_engine_link">
    <visual>
      <geometry>
        <mesh filename="package://wamv_description/models/engine/mesh/engine.dae"/>
      </geometry>
    </visual>
    <collision name="front_left_engine_vertical_axis_collision">
      <origin rpy="0 0 0" xyz="-0.16 0 -0.24"/>
      <geometry>
        <box size="0.2 0.15 0.83"/>
      </geometry>
    </collision>
    <collision name="front_left_engine_rear_end_collision">
      <origin rpy="0 0 0" xyz="-0.34 0 0.12"/>
      <geometry>
        <box size="0.12 0.15 0.12"/>
      </geometry>
    </collision>
    <inertial>
      <mass value="15"/>
      <inertia ixx="0.889245" ixy="0.0" ixz="0.0" iyy="0.911125" iyz="0.0" izz="0.078125"/>
    </inertial>
  </link>
  <link name="wamv/front_left_propeller_link">
    <visual>
      <geometry>
        <mesh filename="package://wamv_description/models/propeller/mesh/propeller.dae"/>
      </geometry>
    </visual>
    <collision name="front_left_propeller_collision">
      <origin rpy="0 1.57 0" xyz="-0.08 0 0"/>
      <geometry>
        <cylinder length="0.18" radius="0.24"/>
      </geometry>
    </collision>
    <inertial>
      <mass value="0.5"/>
      <inertia ixx="0.008545" ixy="0.0" ixz="0.0" iyy="0.008545" iyz="0.0" izz="0.0144"/>
    </inertial>
  </link>
  <joint name="wamv/front_left_chassis_engine_joint" type="revolute">
    <axis xyz="0 0 1"/>
    <limit effort="10" lower="-3.141592653589793" upper="3.141592653589793" velocity="10"/>
    <origin rpy="0.0 0.0 -0.7854" xyz="1.1 1 0"/>
    <parent link="wamv/base_link"/>
    <child link="wamv/front_left_engine_link"/>
  </joint>
  <joint name="wamv/front_left_engine_propeller_joint" type="continuous">
    <axis rpy="0 0 0" xyz="1 0 0"/>
    <parent link="wamv/front_left_engine_link"/>
    <child link="wamv/front_left_propeller_link"/>
    <origin rpy="0 0 0" xyz="-0.278156 0 -0.509371"/>
    <limit effort="100" velocity="100"/>
    <dynamics damping="0.05" friction="0.05"/>
  </joint>
  <link name="wamv/front_right_engine_link">
    <visual>
      <geometry>
        <mesh filename="package://wamv_description/models/engine/mesh/engine.dae"/>
      </geometry>
    </visual>
    <collision name="front_right_engine_vertical_axis_collision">
      <origin rpy="0 0 0" xyz="-0.16 0 -0.24"/>
      <geometry>
        <box size="0.2 0.15 0.83"/>
      </geometry>
    </collision>
    <collision name="front_right_engine_rear_end_collision">
      <origin rpy="0 0 0" xyz="-0.34 0 0.12"/>
      <geometry>
        <box size="0.12 0.15 0.12"/>
      </geometry>
    </collision>
    <inertial>
      <mass value="15"/>
      <inertia ixx="0.889245" ixy="0.0" ixz="0.0" iyy="0.911125" iyz="0.0" izz="0.078125"/>
    </inertial>
  </link>
  <link name="wamv/front_right_propeller_link">
    <visual>
      <geometry>
        <mesh filename="package://wamv_description/models/propeller/mesh/propeller.dae"/>
      </geometry>
    </visual>
    <collision name="front_right_propeller_collision">
      <origin rpy="0 1.57 0" xyz="-0.08 0 0"/>
      <geometry>
        <cylinder length="0.18" radius="0.24"/>
      </geometry>
    </collision>
    <inertial>
      <mass value="0.5"/>
      <inertia ixx="0.008545" ixy="0.0" ixz="0.0" iyy="0.008545" iyz="0.0" izz="0.0144"/>
    </inertial>
  </link>
  <joint name="wamv/front_right_chassis_engine_joint" type="revolute">
    <axis xyz="0 0 1"/>
    <limit effort="10" lower="-3.141592653589793" upper="3.141592653589793" velocity="10"/>
    <origin rpy="0.0 0.0 0.7854" xyz="1.1 -1 0"/>
    <parent link="wamv/base_link"/>
    <child link="wamv/front_right_engine_link"/>
  </joint>
  <joint name="wamv/front_right_engine_propeller_joint" type="continuous">
    <axis rpy="0 0 0" xyz="1 0 0"/>
    <parent link="wamv/front_right_engine_link"/>
    <child link="wamv/front_right_propeller_link"/>
    <origin rpy="0 0 0" xyz="-0.278156 0 -0.509371"/>
    <limit effort="100" velocity="100"/>
    <dynamics damping="0.05" friction="0.05"/>
  </joint>
  <link name="wamv/back_left_engine_link">
    <visual>
      <geometry>
        <mesh filename="package://wamv_description/models/engine/mesh/engine.dae"/>
      </geometry>
    </visual>
    <collision name="back_left_engine_vertical_axis_collision">
      <origin rpy="0 0 0" xyz="-0.16 0 -0.24"/>
      <geometry>
        <box size="0.2 0.15 0.83"/>
      </geometry>
    </collision>
    <collision name="back_left_engine_rear_end_collision">
      <origin rpy="0 0 0" xyz="-0.34 0 0.12"/>
      <geometry>
        <box size="0.12 0.15 0.12"/>
      </geometry>
    </collision>
    <inertial>
      <mass value="15"/>
      <inertia ixx="0.889245" ixy="0.0" ixz="0.0" iyy="0.911125" iyz="0.0" izz="0.078125"/>
    </inertial>
  </link>
  <link name="wamv/back_left_propeller_link">
    <visual>
      <geometry>
        <mesh filename="package://wamv_description/models/propeller/mesh/propeller.dae"/>
      </geometry>
    </visual>
    <collision name="back_left_propeller_collision">
      <origin rpy="0 1.57 0" xyz="-0.08 0 0"/>
      <geometry>
        <cylinder length="0.18" radius="0.24"/>
      </geometry>
    </collision>
    <inertial>
      <mass value="0.5"/>
      <inertia ixx="0.008545" ixy="0.0" ixz="0.0" iyy="0.008545" iyz="0.0" izz="0.0144"/>
    </inertial>
  </link>
  <joint name="wamv/back_left_chassis_engine_joint" type="revolute">
    <axis xyz="0 0 1"/>
    <limit effort="10" lower="-3.141592653589793" upper="3.141592653589793" velocity="10"/>
    <origin rpy="0.0 0.0 0.7854" xyz="-2.4 1 0"/>
    <parent link="wamv/base_link"/>
    <child link="wamv/back_left_engine_link"/>
  </joint>
  <joint name="wamv/back_left_engine_propeller_joint" type="continuous">
    <axis rpy="0 0 0" xyz="1 0 0"/>
    <parent link="wamv/back_left_engine_link"/>
    <child link="wamv/back_left_propeller_link"/>
    <origin rpy="0 0 0" xyz="-0.278156 0 -0.509371"/>
    <limit effort="100" velocity="100"/>
    <dynamics damping="0.05" friction="0.05"/>
  </joint>
  <link name="wamv/back_right_engine_link">
    <visual>
      <geometry>
        <mesh filename="package://wamv_description/models/engine/mesh/engine.dae"/>
      </geometry>
    </visual>
    <collision name="back_right_engine_vertical_axis_collision">
      <origin rpy="0 0 0" xyz="-0.16 0 -0.24"/>
      <geometry>
        <box size="0.2 0.15 0.83"/>
      </geometry>
    </collision>
    <collision name="back_right_engine_rear_end_collision">
      <origin rpy="0 0 0" xyz="-0.34 0 0.12"/>
      <geometry>
        <box size="0.12 0.15 0.12"/>
      </geometry>
    </collision>
    <inertial>
      <mass value="15"/>
      <inertia ixx="0.889245" ixy="0.0" ixz="0.0" iyy="0.911125" iyz="0.0" izz="0.078125"/>
    </inertial>
  </link>
  <link name="wamv/back_right_propeller_link">
    <visual>
      <geometry>
        <mesh filename="package://wamv_description/models/propeller/mesh/propeller.dae"/>
      </geometry>
    </visual>
    <collision name="back_right_propeller_collision">
      <origin rpy="0 1.57 0" xyz="-0.08 0 0"/>
      <geometry>
        <cylinder length="0.18" radius="0.24"/>
      </geometry>
    </collision>
    <inertial>
      <mass value="0.5"/>
      <inertia ixx="0.008545" ixy="0.0" ixz="0.0" iyy="0.008545" iyz="0.0" izz="0.0144"/>
    </inertial>
  </link>
  <joint name="wamv/back_right_chassis_engine_joint" type="revolute">
    <axis xyz="0 0 1"/>
    <limit effort="10" lower="-3.141592653589793" upper="3.141592653589793" velocity="10"/>
    <origin rpy="0.0 0.0 -0.7854" xyz="-2.4 -1 0"/>
    <parent link="wamv/base_link"/>
    <child link="wamv/back_right_engine_link"/>
  </joint>
  <joint name="wamv/back_right_engine_propeller_joint" type="continuous">
    <axis rpy="0 0 0" xyz="1 0 0"/>
    <parent link="wamv/back_right_engine_link"/>
    <child link="wamv/back_right_propeller_link"/>
    <origin rpy="0 0 0" xyz="-0.278156 0 -0.509371"/>
    <limit effort="100" velocity="100"/>
    <dynamics damping="0.05" friction="0.05"/>
  </joint>
  <gazebo>
    <plugin filename="gz-sim-thruster-system" name="gz::sim::systems::Thruster">
      <joint_name>wamv/front_left_engine_propeller_joint</joint_name>
      <thrust_coefficient>0.004422</thrust_coefficient>
      <fluid_density>1000</fluid_density>
      <propeller_diameter>0.2</propeller_diameter>
      <velocity_control>true</velocity_control>
      <!-- max total thrust / 2 -->
      <max_thrust_cmd>2353.53383667818</max_thrust_cmd>
      <namespace>wamv</namespace>
      <topic>thrusters/front_left/thrust</topic>
      <!-- Not used by Gazebo but used to run the bridge easily -->
      <name>front_left</name>
    </plugin>
    <plugin filename="gz-sim-joint-position-controller-system" name="gz::sim::systems::JointPositionController">
      <joint_name>wamv/front_left_chassis_engine_joint</joint_name>
      <use_velocity_commands>true</use_velocity_commands>
      <topic>wamv/thrusters/front_left/pos</topic>
      <!-- Not used by Gazebo but used to run the bridge easily -->
      <name>front_left</name>
    </plugin>
  </gazebo>
  <gazebo>
    <plugin filename="gz-sim-thruster-system" name="gz::sim::systems::Thruster">
      <joint_name>wamv/front_right_engine_propeller_joint</joint_name>
      <thrust_coefficient>0.004422</thrust_coefficient>
      <fluid_density>1000</fluid_density>
      <propeller_diameter>0.2</propeller_diameter>
      <velocity_control>true</velocity_control>
      <!-- max total thrust / 2 -->
      <max_thrust_cmd>2353.53383667818</max_thrust_cmd>
      <namespace>wamv</namespace>
      <topic>thrusters/front_right/thrust</topic>
      <!-- Not used by Gazebo but used to run the bridge easily -->
      <name>front_right</name>
    </plugin>
    <plugin filename="gz-sim-joint-position-controller-system" name="gz::sim::systems::JointPositionController">
      <joint_name>wamv/front_right_chassis_engine_joint</joint_name>
      <use_velocity_commands>true</use_velocity_commands>
      <topic>wamv/thrusters/front_right/pos</topic>
      <!-- Not used by Gazebo but used to run the bridge easily -->
      <name>front_right</name>
    </plugin>
  </gazebo>
  <gazebo>
    <plugin filename="gz-sim-thruster-system" name="gz::sim::systems::Thruster">
      <joint_name>wamv/back_left_engine_propeller_joint</joint_name>
      <thrust_coefficient>0.004422</thrust_coefficient>
      <fluid_density>1000</fluid_density>
      <propeller_diameter>0.2</propeller_diameter>
      <velocity_control>true</velocity_control>
      <!-- max total thrust / 2 -->
      <max_thrust_cmd>2353.53383667818</max_thrust_cmd>
      <namespace>wamv</namespace>
      <topic>thrusters/back_left/thrust</topic>
      <!-- Not used by Gazebo but used to run the bridge easily -->
      <name>back_left</name>
    </plugin>
    <plugin filename="gz-sim-joint-position-controller-system" name="gz::sim::systems::JointPositionController">
      <joint_name>wamv/back_left_chassis_engine_joint</joint_name>
      <use_velocity_commands>true</use_velocity_commands>
      <topic>wamv/thrusters/back_left/pos</topic>
      <!-- Not used by Gazebo but used to run the bridge easily -->
      <name>back_left</name>
    </plugin>
  </gazebo>
  <gazebo>
    <plugin filename="gz-sim-thruster-system" name="gz::sim::systems::Thruster">
      <joint_name>wamv/back_right_engine_propeller_joint</joint_name>
      <thrust_coefficient>0.004422</thrust_coefficient>
      <fluid_density>1000</fluid_density>
      <propeller_diameter>0.2</propeller_diameter>
      <velocity_control>true</velocity_control>
      <!-- max total thrust / 2 -->
      <max_thrust_cmd>2353.53383667818</max_thrust_cmd>
      <namespace>wamv</namespace>
      <topic>thrusters/back_right/thrust</topic>
      <!-- Not used by Gazebo but used to run the bridge easily -->
      <name>back_right</name>
    </plugin>
    <plugin filename="gz-sim-joint-position-controller-system" name="gz::sim::systems::JointPositionController">
      <joint_name>wamv/back_right_chassis_engine_joint</joint_name>
      <use_velocity_commands>true</use_velocity_commands>
      <topic>wamv/thrusters/back_right/pos</topic>
      <!-- Not used by Gazebo but used to run the bridge easily -->
      <name>back_right</name>
    </plugin>
  </gazebo>
  <!--Gazebo Plugin for simulating WAM-V dynamics-->
  <gazebo>
    <!-- Left hull -->
    <plugin filename="libSurface.so" name="vrx::Surface">
      <link_name>wamv/base_link</link_name>
      <hull_length>4.9</hull_length>
      <hull_radius>0.213</hull_radius>
      <fluid_level>0</fluid_level>
      <points>
        <point>0.6 1.03 0</point>
        <point>-1.4 1.03 0</point>
      </points>
      <wavefield>
        <topic>/vrx/wavefield/parameters</topic>
      </wavefield>
    </plugin>
    <!-- Right hull -->
    <plugin filename="libSurface.so" name="vrx::Surface">
      <link_name>wamv/base_link</link_name>
      <hull_length>4.9</hull_length>
      <hull_radius>0.213</hull_radius>
      <fluid_level>0</fluid_level>
      <points>
        <point>0.6 -1.03 0</point>
        <point>-1.4 -1.03 0</point>
      </points>
      <wavefield>
        <topic>/vrx/wavefield/parameters</topic>
      </wavefield>
    </plugin>
    <plugin filename="libSimpleHydrodynamics.so" name="vrx::SimpleHydrodynamics">
      <link_name>wamv/base_link</link_name>
      <!-- Added mass -->
      <xDotU>0.0</xDotU>
      <yDotV>0.0</yDotV>
      <nDotR>0.0</nDotR>
      <!-- Linear and quadratic drag -->
      <xU>100.0</xU>
      <xUU>150.0</xUU>
      <yV>100.0</yV>
      <yVV>100.0</yVV>
      <zW>500.0</zW>
      <kP>300.0</kP>
      <kPP>600.0</kPP>
      <mQ>900.0</mQ>
      <mQQ>900.0</mQQ>
      <nR>800.0</nR>
      <nRR>800.0</nRR>
    </plugin>
  </gazebo>
  <!-- === [Un]lock the robot to the world === -->
  <gazebo>
    <plugin filename="gz-sim-detachable-joint-system" name="gz::sim::systems::DetachableJoint">
      <parent_link>wamv/base_link</parent_link>
      <child_model>platform</child_model>
      <child_link>dummy_upper</child_link>
      <topic>/vrx/release</topic>
      <suppress_child_warning>true</suppress_child_warning>
    </plugin>
  </gazebo>
  <!-- === TF === -->
  <!-- Publish robot state information -->
  <gazebo>
    <plugin filename="libgz-sim-pose-publisher-system.so" name="gz::sim::systems::PosePublisher">
      <publish_link_pose>false</publish_link_pose>
      <publish_sensor_pose>true</publish_sensor_pose>
      <publish_collision_pose>false</publish_collision_pose>
      <publish_visual_pose>false</publish_visual_pose>
      <publish_nested_model_pose>false</publish_nested_model_pose>
      <publish_model_pose>false</publish_model_pose>
      <use_pose_vector_msg>true</use_pose_vector_msg>
      <static_publisher>false</static_publisher>
      <static_update_frequency>1</static_update_frequency>
    </plugin>
    <plugin filename="gz-sim-joint-state-publisher-system" name="gz::sim::systems::JointStatePublisher">
    </plugin>
  </gazebo>
  <link name="wamv/imu_wamv_link">
    <visual name="imu_wamv_visual">
      &gt;
        
      <geometry>
        <box size="0.05 0.025 0.005"/>
      </geometry>
      <material name="imu_wamv_visual_material">
        <color rgba="1.0 0.0 00 1.0"/>
      </material>
    </visual>
    <collision name="imu_wamv_collision">
      &gt;
        
      <geometry>
        <box size="0.05 0.025 0.005"/>
      </geometry>
    </collision>
    <inertial>
      <mass value="0.1"/>
      <inertia ixx="0.00000542" ixy="0.0" ixz="0.0" iyy="0.00002104" iyz="0.0" izz="0.00002604"/>
    </inertial>
  </link>
  <joint name="wamv/imu_wamv_joint" type="revolute">
    <axis xyz="0 0 1"/>
    <limit effort="1000.0" lower="0.0" upper="0" velocity="0"/>
    <origin rpy="0.0 0.0 0.0" xyz="-0.65 0.0 1.3"/>
    <parent link="wamv/base_link"/>
    <child link="wamv/imu_wamv_link"/>
  </joint>
  <gazebo reference="wamv/imu_wamv_link">
    <sensor name="imu_wamv_sensor" type="imu">
      <update_rate>100</update_rate>
      <imu>
        <angular_velocity>
          <x>
            <noise type="gaussian">
              <mean>0</mean>
              <stddev>0.009</stddev>
              <bias_mean>0.00075</bias_mean>
              <bias_stddev>0.005</bias_stddev>
              <dynamic_bias_stddev>0.00002</dynamic_bias_stddev>
              <dynamic_bias_correlation_time>400.0</dynamic_bias_correlation_time>
              <precision>0.00025</precision>
            </noise>
          </x>
          <y>
            <noise type="gaussian">
              <mean>0</mean>
              <stddev>0.009</stddev>
              <bias_mean>0.00075</bias_mean>
              <bias_stddev>0.005</bias_stddev>
              <dynamic_bias_stddev>0.00002</dynamic_bias_stddev>
              <dynamic_bias_correlation_time>400.0</dynamic_bias_correlation_time>
              <precision>0.00025</precision>
            </noise>
          </y>
          <z>
            <noise type="gaussian">
              <mean>0</mean>
              <stddev>0.009</stddev>
              <bias_mean>0.00075</bias_mean>
              <bias_stddev>0.005</bias_stddev>
              <dynamic_bias_stddev>0.00002</dynamic_bias_stddev>
              <dynamic_bias_correlation_time>400.0</dynamic_bias_correlation_time>
              <precision>0.00025</precision>
            </noise>
          </z>
        </angular_velocity>
        <linear_acceleration>
          <x>
            <noise type="gaussian">
              <mean>0</mean>
              <stddev>0.021</stddev>
              <bias_mean>0.05</bias_mean>
              <bias_stddev>0.0075</bias_stddev>
              <dynamic_bias_stddev>0.000375</dynamic_bias_stddev>
              <dynamic_bias_correlation_time>175.0</dynamic_bias_correlation_time>
              <precision>0.005</precision>
            </noise>
          </x>
          <y>
            <noise type="gaussian">
              <mean>0</mean>
              <stddev>0.021</stddev>
              <bias_mean>0.05</bias_mean>
              <bias_stddev>0.0075</bias_stddev>
              <dynamic_bias_stddev>0.000375</dynamic_bias_stddev>
              <dynamic_bias_correlation_time>175.0</dynamic_bias_correlation_time>
              <precision>0.005</precision>
            </noise>
          </y>
          <z>
            <noise type="gaussian">
              <mean>0</mean>
              <stddev>0.021</stddev>
              <bias_mean>0.05</bias_mean>
              <bias_stddev>0.0075</bias_stddev>
              <dynamic_bias_stddev>0.000375</dynamic_bias_stddev>
              <dynamic_bias_correlation_time>175.0</dynamic_bias_correlation_time>
              <precision>0.005</precision>
            </noise>
          </z>
        </linear_acceleration>
        <orientation_reference_frame>
          <localization>ENU</localization>
        </orientation_reference_frame>
      </imu>
    </sensor>
  </gazebo>
  <link name="wamv/gps_wamv_link">
    <visual name="gps_wamv_visual">
      <geometry>
        <mesh filename="package://wamv_gazebo/models/gps/mesh/gps.dae"/>
      </geometry>
    </visual>
    <collision name="gps_wamv_collision_base">
      <origin rpy="0 0 0" xyz="0 0 0.025"/>
      <geometry>
        <cylinder length="0.05" radius="0.015"/>
      </geometry>
    </collision>
    <collision name="gps_wamv_collision_antenna">
      <origin rpy="0 0 0" xyz="0 0 0.11"/>
      <geometry>
        <cylinder length="0.1" radius="0.15"/>
      </geometry>
    </collision>
    <inertial>
      <mass value="1"/>
      <inertia ixx="0.006458" ixy="0.0" ixz="0.0" iyy="0.006458" iyz="0.0" izz="0.01125"/>
    </inertial>
  </link>
  <joint name="wamv/gps_wamv_joint" type="revolute">
    <axis xyz="0 0 1"/>
    <limit effort="1000.0" lower="0.0" upper="0" velocity="0"/>
    <origin rpy="0.0 0.0 0.0" xyz="-0.65 0.0 1.3"/>
    <parent link="wamv/base_link"/>
    <child link="wamv/gps_wamv_link"/>
  </joint>
  <gazebo reference="wamv/gps_wamv_link">
    <sensor name="navsat" type="navsat">
      <always_on>1</always_on>
      <update_rate>20</update_rate>
      <!--<topic>${namespace}/${sensor_namespace}gps/gps/fix</topic>-->
    </sensor>
  </gazebo>
  <link name="wamv/cpu_cases_link">
    <visual>
      <origin rpy="0 0 0" xyz="0.073 0 -1.53"/>
      <geometry>
        <mesh filename="package://vrx_gazebo/models/cpu_cases/mesh/cpu_cases.dae"/>
      </geometry>
    </visual>
    <collision name="cpu_case_1_collision">
      <origin rpy="0 0 0" xyz="0.185 0 0"/>
      <geometry>
        <box size="0.595 0.83 0.47"/>
      </geometry>
    </collision>
    <collision name="cpu_case_2_collision">
      <origin rpy="0 0 0" xyz="-0.3 0 -0.092"/>
      <geometry>
        <box size="0.375 0.64 0.28"/>
      </geometry>
    </collision>
    <inertial>
      <mass value="20"/>
      <inertia ixx="1.51633333333333" ixy="0" ixz="0" iyy="1.93633333333333" iyz="0" izz="2.71633333333333"/>
    </inertial>
  </link>
  <joint name="wamv/chasis_cpu_cases_joint" type="fixed">
    <origin rpy="0 0 0" xyz="-0.15 0 1.53"/>
    <parent link="wamv/base_link"/>
    <child link="wamv/cpu_cases_link"/>
  </joint>
  <gazebo reference="wamv/cpu_cases_link">
    <visual>
      <material>
        <diffuse>1.0 1.0 1.0</diffuse>
        <specular>1.0 1.0 1.0</specular>
        <pbr>
          <metal>
            <albedo_map>model://vrx_gazebo/models/cpu_cases/mesh/cpu_cases_Albedo.png</albedo_map>
            <normal_map>model://vrx_gazebo/models/cpu_cases/mesh/cpu_cases_Normal.png</normal_map>
            <roughness_map>model://vrx_gazebo/models/cpu_cases/mesh/cpu_cases_Roughness.png</roughness_map>
            <metalness_map>model://vrx_gazebo/models/cpu_cases/mesh/cpu_cases_Metalness.png</metalness_map>
          </metal>
        </pbr>
      </material>
    </visual>
  </gazebo>
</robot>
